<?xml version="1.0"?>
<robot xmlns:xacro="http://www.ros.org/wiki/xacro" name="vectorsense_drone">

  <!-- THE GHOST CORE: Mathematically Perfect Physics Skeleton -->
  <link name="base_link">
    <!-- PHYSICS CORE: Zero-Visual, Perfectly Symmetric Intertials -->
    <inertial>
      <origin xyz="0 0 0" rpy="0 0 0"/>
      <mass value="2.5"/>
      <inertia ixx="0.03" ixy="0" ixz="0" iyy="0.03" iyz="0" izz="0.06"/>
    </inertial>
    
    <!-- COLLISION CORE: Primitive-only to prevent mesh shears -->
    <collision name="base_collision">
      <origin xyz="0 0 0" rpy="0 0 0"/>
      <geometry>
        <box size="0.2 0.2 0.1"/>
      </geometry>
    </collision>

    <!-- VISUAL SKINS: Weightless CAD layers (No Collision / No Inertial) -->
    <visual name="skin_base">
      <geometry>
        <mesh filename="package://vectorsense_megacomplex/meshes/DroneFYDPBase.stl" scale="0.001 0.001 0.001"/>
      </geometry>
    </visual>
    
    <visual name="skin_xbeam">
      <origin xyz="0 0 0.05" rpy="0 0 0"/>
      <geometry>
        <mesh filename="package://vectorsense_megacomplex/meshes/Xbeam.stl" scale="0.001 0.001 0.001"/>
      </geometry>
    </visual>

    <visual name="skin_beam180">
      <origin xyz="0 0 0.05" rpy="0 0 1.5708"/>
      <geometry>
        <mesh filename="package://vectorsense_megacomplex/meshes/180beam.stl" scale="0.001 0.001 0.001"/>
      </geometry>
    </visual>

    <visual name="skin_top_plate">
      <origin xyz="0 0 0.1" rpy="0 0 0"/>
      <geometry>
        <mesh filename="package://vectorsense_megacomplex/meshes/top_plate.stl" scale="0.001 0.001 0.001"/>
      </geometry>
    </visual>
  </link>

  <!-- MOTORS: Exact Symmetry (X,Y = +/- 0.225m) -->
  <xacro:macro name="motor" params="name x y index direction">
    <link name="motor_${name}">
      <!-- Weightless visual anchor -->
      <visual>
        <geometry>
          <mesh filename="package://vectorsense_megacomplex/meshes/motor_attachment.stl" scale="0.001 0.001 0.001"/>
        </geometry>
      </visual>
      <!-- Small placeholder inertial to satisfy some solvers, though visual-only is intended -->
      <inertial>
        <mass value="0.001"/>
        <inertia ixx="0.0001" ixy="0" ixz="0" iyy="0.0001" iyz="0" izz="0.0001"/>
      </inertial>
    </link>

    <joint name="motor_${name}_joint" type="continuous">
      <parent link="base_link"/>
      <child link="motor_${name}"/>
      <origin xyz="${x} ${y} 0.08" rpy="0 0 0"/>
      <axis xyz="0 0 1"/>
    </joint>

    <gazebo>
      <plugin filename="gz-sim-multicopter-motor-model-system" name="gz::sim::systems::MulticopterMotorModel">
        <robotNamespace>vectorsense</robotNamespace>
        <jointName>motor_${name}_joint</jointName>
        <linkName>motor_${name}</linkName>
        <turningDirection>${direction}</turningDirection>
        <timeConstantUp>0.0125</timeConstantUp>
        <timeConstantDown>0.025</timeConstantDown>
        <maxRotVelocity>1500</maxRotVelocity>
        <motorConstant>8.54858e-06</motorConstant>
        <momentConstant>0.016</momentConstant>
        <commandSubTopic>command/motor_speed</commandSubTopic>
        <motorNumber>${index}</motorNumber>
        <rotorDragCoefficient>8.06428e-05</rotorDragCoefficient>
        <rollingMomentCoefficient>1e-06</rollingMomentCoefficient>
        <rotorVelocitySlowdownSim>10</rotorVelocitySlowdownSim>
      </plugin>
    </gazebo>
  </xacro:macro>

  <xacro:motor name="fr" x="0.225" y="-0.225" index="0" direction="ccw"/>
  <xacro:motor name="fl" x="0.225" y="0.225" index="1" direction="cw"/>
  <xacro:motor name="br" x="-0.225" y="-0.225" index="2" direction="cw"/>
  <xacro:motor name="bl" x="-0.225" y="0.225" index="3" direction="ccw"/>

  <gazebo>
    <plugin filename="gz-sim-multicopter-velocity-control-system" name="gz::sim::systems::MulticopterVelocityControl">
      <robotNamespace>vectorsense</robotNamespace>
      <commandSubTopic>cmd_vel</commandSubTopic>
      <enableAngleControl>true</enableAngleControl>
      <enableVelocityControl>true</enableVelocityControl>
      <maximumLinearVelocity>15.0</maximumLinearVelocity>
      <maximumAngularVelocity>5.0</maximumAngularVelocity>
    </plugin>
    
    <!-- State Publisher for Odometry -->
    <plugin filename="gz-sim-odometry-publisher-system" name="gz::sim::systems::OdometryPublisher">
      <dimensions>3</dimensions>
    </plugin>
  </gazebo>

</robot>
